Workbook

Sheet Índice
B2: ÍNDICE DO ARQUIVO
B4: Nº | C4: Planilha | D4: Descrição
B5: 1 | C5: Renúncias Fiscais Sudam-Sudene | D5: Redução 75% Projeto Setor Prioritário e Redução Por Reinvestimento - Período 2015 a 2023 (11.310 registros)
B6: 2 | C6: IPCA_Fatores | D6: Fatores de correção IPCA por ano (2015-2023)
B7: 3 | C7: Resumo_por_Empresa | D7: Totais consolidados por empresa (2.247 empresas)
B9: Última atualização: 09/07/2026

Sheet Renúncias Fiscais Sudam-Sudene
A1: Ano-Calendário | B1: CNPJ | C1: Beneficiário | D1: Nome Fantasia | E1: UF | F1: Município | G1: CNAE | H1: Tipo de Renúncia | I1: Benefício Fiscal | J1: Valor Renunciado(R$) | K1: Valor Renunciado atualizado pelo IPCA até 31/05/2026 (R$)
A2: 2018 | B2: 11.844.663/0001-09 | C2: 1TELECOM SERVICOS DE TECNOLOGIA EM INTERNET LTDA | D2: 1TELECOM | E2: PERNAMBUCO | F2: RECIFE | G2: 61108 - Telecomunicações por fio | H2: Declarado pelo Contribuinte para Apuração do IRPJ e da CSLL | I2: Sudam/Sudene - Redução 75% Projeto Setor Prioritário | J2: 658675.67 | K2: =J2*_xlfn.XLOOKUP(A2,IPCA_Fatores!$A$2:$A$10,IPCA_Fatores!$C$2:$C$10) -> 986691.23
A3: 2019 | B3: 11.844.663/0001-09 | C3: 1TELECOM SERVICOS DE TECNOLOGIA EM INTERNET LTDA | D3: 1TELECOM | E3: PERNAMBUCO | F3: RECIFE | G3: 61108 - Telecomunicações por fio | H3: Declarado pelo Contribuinte para Apuração do IRPJ e da CSLL | I3: Sudam/Sudene - Redução 75% Projeto Setor Prioritário | J3: 251732.73 | K3: =J3*_xlfn.XLOOKUP(A3,IPCA_Fatores!$A$2:$A$10,IPCA_Fatores!$C$2:$C$10) -> 361512.56
A4: 2020 | B4: 11.844.663/0001-09 | C4: 1TELECOM SERVICOS DE TECNOLOGIA EM INTERNET LTDA | D4: 1TELECOM | E4: PERNAMBUCO | F4: RECIFE | G4: 61108 - Telecomunicações por fio | H4: Declarado pelo Contribuinte para Apuração do IRPJ e da CSLL | I4: Sudam/Sudene - Redução 75% Projeto Setor Prioritário | J4: 376707.82 | K4: =J4*_xlfn.XLOOKUP(A4,IPCA_Fatores!$A$2:$A$10,IPCA_Fatores!$C$2:$C$10) -> 517593.64
A5: 2021 | B5: 11.844.663/0001-09 | C5: 1TELECOM SERVICOS DE TECNOLOGIA EM INTERNET LTDA | D5: 1TELECOM | E5: PERNAMBUCO | F5: RECIFE | G5: 61108 - Telecomunicações por fio | H5: Declarado pelo Contribuinte para Apuração do IRPJ e da CSLL | I5: Sudam/Sudene - Redução 75% Projeto Setor Prioritário | J5: 348957.85 | K5: =J5*_xlfn.XLOOKUP(A5,IPCA_Fatores!$A$2:$A$10,IPCA_Fatores!$C$2:$C$10) -> 435640.01
A6: 2022 | B6: 11.844.663/0001-09 | C6: 1TELECOM SERVICOS DE TECNOLOGIA EM INTERNET LTDA | D6: 1TELECOM | E6: PERNAMBUCO | F6: RECIFE | G6: 61108 - Telecomunicações por fio | H6: Declarado pelo Contribuinte para Apuração do IRPJ e da CSLL | I6: Sudam/Sudene - Redução 75% Projeto Setor Prioritário | J6: 419468.24 | K6: =J6*_xlfn.XLOOKUP(A6,IPCA_Fatores!$A$2:$A$10,IPCA_Fatores!$C$2:$C$10) -> 495004.62
A7: 2023 | B7: 11.844.663/0001-09 | C7: 1TELECOM SERVICOS DE TECNOLOGIA EM INTERNET LTDA | D7: 1TELECOM | E7: PERNAMBUCO | F7: RECIFE | G7: 61108 - Telecomunicações por fio | H7: Declarado pelo Contribuinte para Apuração do IRPJ e da CSLL | I7: Sudam/Sudene - Redução 75% Projeto Setor Prioritário | J7: 2181220.8 | K7: =J7*_xlfn.XLOOKUP(A7,IPCA_Fatores!$A$2:$A$10,IPCA_Fatores!$C$2:$C$10) -> 2460339.8
A8: 2023 | B8: 42.762.204/0001-00 | C8: 2 J COMERCIAL LTDA | E8: ESPIRITO SANTO | F8: NOVA VENÉCIA | G8: 46371 - Comércio atacadista especializado em produtos alimentícios não especificados anteriormente | H8: Declarado pelo Contribuinte para Apuração do IRPJ e da CSLL | I8: Sudam/Sudene - Redução 75% Projeto Setor Prioritário | J8: 791713.05 | K8: =J8*_xlfn.XLOOKUP(A8,IPCA_Fatores!$A$2:$A$10,IPCA_Fatores!$C$2:$C$10) -> 893024.27
A9: 2023 | B9: 42.762.204/0001-00 | C9: 2 J COMERCIAL LTDA | E9: ESPIRITO SANTO | F9: NOVA VENÉCIA | G9: 46371 - Comércio atacadista especializado em produtos alimentícios não especificados anteriormente | H9: Declarado pelo Contribuinte para Apuração do IRPJ e da CSLL | I9: Sudam/Sudene - Redução por Reinvestimento | J9: 79171.31 | K9: =IFERROR(J9*VLOOKUP(A9,IPCA_Fatores!$A$2:$C$10,3,FALSE),J9) -> 89302.432
A10: 2018 | B10: 19.675.900/0001-67 | C10: 3CAFFI INDUSTRIA E COMERCIO DE CAPSULAS S.A | E10: MINAS GERAIS | F10: MONTES CLAROS | G10: 10813 - Torrefação e moagem de café | H10: Declarado pelo Contribuinte para Apuração do IRPJ e da CSLL | I10: Sudam/Sudene - Redução 75% Projeto Setor Prioritário | J10: 1563799.9 | K10: =J10*_xlfn.XLOOKUP(A10,IPCA_Fatores!$A$2:$A$10,IPCA_Fatores!$C$2:$C$10) -> 2342560.6
A11: 2018 | B11: 19.675.900/0001-67 | C11: 3CAFFI INDUSTRIA E COMERCIO DE CAPSULAS S.A | E11: MINAS GERAIS | F11: MONTES CLAROS | G11: 10813 - Torrefação e moagem de café | H11: Declarado pelo Contribuinte para Apuração do IRPJ e da CSLL | I11: Sudam/Sudene - Redução por Reinvestimento | J11: 94907.99 | K11: =IFERROR(J11*VLOOKUP(A11,IPCA_Fatores!$A$2:$C$10,3,FALSE),J11) -> 142171.46
A12: 2019 | B12: 19.675.900/0001-67 | C12: 3CAFFI INDUSTRIA E COMERCIO DE CAPSULAS S.A | E12: MINAS GERAIS | F12: MONTES CLAROS | G12: 10813 - Torrefação e moagem de café | H12: Declarado pelo Contribuinte para Apuração do IRPJ e da CSLL | I12: Sudam/Sudene - Redução 75% Projeto Setor Prioritário | J12: 2948345.1 | K12: =J12*_xlfn.XLOOKUP(A12,IPCA_Fatores!$A$2:$A$10,IPCA_Fatores!$C$2:$C$10) -> 4234108.9
A13: 2019 | B13: 19.675.900/0001-67 | C13: 3CAFFI INDUSTRIA E COMERCIO DE CAPSULAS S.A | E13: MINAS GERAIS | F13: MONTES CLAROS | G13: 10813 - Torrefação e moagem de café | H13: Declarado pelo Contribuinte para Apuração do IRPJ e da CSLL | I13: Sudam/Sudene - Redução por Reinvestimento | J13: 107493.67 | K13: =IFERROR(J13*VLOOKUP(A13,IPCA_Fatores!$A$2:$C$10,3,FALSE),J13) -> 154371.31
A14: 2020 | B14: 19.675.900/0001-67 | C14: 3CAFFI INDUSTRIA E COMERCIO DE CAPSULAS S.A | E14: MINAS GERAIS | F14: MONTES CLAROS | G14: 10813 - Torrefação e moagem de café | H14: Declarado pelo Contribuinte para Apuração do IRPJ e da CSLL | I14: Sudam/Sudene - Redução 75% Projeto Setor Prioritário | J14: 3262879.8 | K14: =J14*_xlfn.XLOOKUP(A14,IPCA_Fatores!$A$2:$A$10,IPCA_Fatores!$C$2:$C$10) -> 4483171.7
A15: 2020 | B15: 19.675.900/0001-67 | C15: 3CAFFI INDUSTRIA E COMERCIO DE CAPSULAS S.A | E15: MINAS GERAIS | F15: MONTES CLAROS | G15: 10813 - Torrefação e moagem de café | H15: Declarado pelo Contribuinte para Apuração do IRPJ e da CSLL | I15: Sudam/Sudene - Redução por Reinvestimento | J15: 196846.52 | K15: =IFERROR(J15*VLOOKUP(A15,IPCA_Fatores!$A$2:$C$10,3,FALSE),J15) -> 270465.6
A16: 2021 | B16: 19.675.900/0001-67 | C16: 3CAFFI INDUSTRIA E COMERCIO DE CAPSULAS S.A | E16: MINAS GERAIS | F16: MONTES CLAROS | G16: 10813 - Torrefação e moagem de café | H16: Declarado pelo Contribuinte para Apuração do IRPJ e da CSLL | I16: Sudam/Sudene - Redução 75% Projeto Setor Prioritário | J16: 4955151.4 | K16: =J16*_xlfn.XLOOKUP(A16,IPCA_Fatores!$A$2:$A$10,IPCA_Fatores!$C$2:$C$10) -> 6186025.7
A17: 2021 | B17: 19.675.900/0001-67 | C17: 3CAFFI INDUSTRIA E COMERCIO DE CAPSULAS S.A | E17: MINAS GERAIS | F17: MONTES CLAROS | G17: 10813 - Torrefação e moagem de café | H17: Declarado pelo Contribuinte para Apuração do IRPJ e da CSLL | I17: Sudam/Sudene - Redução por Reinvestimento | J17: 298389.08 | K17: =IFERROR(J17*VLOOKUP(A17,IPCA_Fatores!$A$2:$C$10,3,FALSE),J17) -> 372509.81
A18: 2022 | B18: 19.675.900/0001-67 | C18: 3CAFFI INDUSTRIA E COMERCIO DE CAPSULAS S.A | E18: MINAS GERAIS | F18: MONTES CLAROS | G18: 10813 - Torrefação e moagem de café | H18: Declarado pelo Contribuinte para Apuração do IRPJ e da CSLL | I18: Sudam/Sudene - Redução 75% Projeto Setor Prioritário | J18: 5871653.1 | K18: =J18*_xlfn.XLOOKUP(A18,IPCA_Fatores!$A$2:$A$10,IPCA_Fatores!$C$2:$C$10) -> 6929000
A19: 2022 | B19: 19.675.900/0001-67 | C19: 3CAFFI INDUSTRIA E COMERCIO DE CAPSULAS S.A | E19: MINAS GERAIS | F19: MONTES CLAROS | G19: 10813 - Torrefação e moagem de café | H19: Declarado pelo Contribuinte para Apuração do IRPJ e da CSLL | I19: Sudam/Sudene - Redução por Reinvestimento | J19: 353379.18 | K19: =IFERROR(J19*VLOOKUP(A19,IPCA_Fatores!$A$2:$C$10,3,FALSE),J19) -> 417014.48
A20: 2023 | B20: 19.675.900/0001-67 | C20: 3CAFFI INDUSTRIA E COMERCIO DE CAPSULAS S.A | E20: MINAS GERAIS | F20: MONTES CLAROS | G20: 10813 - Torrefação e moagem de café | H20: Declarado pelo Contribuinte para Apuração do IRPJ e da CSLL | I20: Sudam/Sudene - Redução 75% Projeto Setor Prioritário | J20: 8091011.3 | K20: =J20*_xlfn.XLOOKUP(A20,IPCA_Fatores!$A$2:$A$10,IPCA_Fatores!$C$2:$C$10) -> 9126374.1
A21: 2023 | B21: 19.675.900/0001-67 | C21: 3CAFFI INDUSTRIA E COMERCIO DE CAPSULAS S.A | E21: MINAS GERAIS | F21: MONTES CLAROS | G21: 10813 - Torrefação e moagem de café | H21: Declarado pelo Contribuinte para Apuração do IRPJ e da CSLL | I21: Sudam/Sudene - Redução por Reinvestimento | J21: 486540.69 | K21: =IFERROR(J21*VLOOKUP(A21,IPCA_Fatores!$A$2:$C$10,3,FALSE),J21) -> 548800.66
A22: 2015 | B22: 08.014.346/0001-50 | C22: 3M MANAUS INDUSTRIA DE PRODUTOS QUIMICOS LTDA | D22: 3M MANAUS | E22: AMAZONAS | F22: MANAUS | G22: 20991 - Fabricação de produtos químicos não especificados anteriormente | H22: Declarado pelo Contribuinte para Apuração do IRPJ e da CSLL | I22: Sudam/Sudene - Redução 75% Projeto Setor Prioritário | J22: 15579466 | K22: =J22*_xlfn.XLOOKUP(A22,IPCA_Fatores!$A$2:$A$10,IPCA_Fatores!$C$2:$C$10) -> 26495314
A23: 2015 | B23: 08.014.346/0001-50 | C23: 3M MANAUS INDUSTRIA DE PRODUTOS QUIMICOS LTDA | D23: 3M MANAUS | E23: AMAZONAS | F23: MANAUS | G23: 20991 - Fabricação de produtos químicos não especificados anteriormente | H23: Declarado pelo Contribuinte para Apuração do IRPJ e da CSLL | I23: Sudam/Sudene - Redução por Reinvestimento | J23: 935657.54 | K23: =IFERROR(J23*VLOOKUP(A23,IPCA_Fatores!$A$2:$C$10,3,FALSE),J23) -> 1591231.7
A24: 2016 | B24: 08.014.346/0001-50 | C24: 3M MANAUS INDUSTRIA DE PRODUTOS QUIMICOS LTDA | D24: 3M MANAUS | E24: AMAZONAS | F24: MANAUS | G24: 20991 - Fabricação de produtos químicos não especificados anteriormente | H24: Declarado pelo Contribuinte para Apuração do IRPJ e da CSLL | I24: Sudam/Sudene - Redução 75% Projeto Setor Prioritário | J24: 26578214 | K24: =J24*_xlfn.XLOOKUP(A24,IPCA_Fatores!$A$2:$A$10,IPCA_Fatores!$C$2:$C$10) -> 42525546
A25: 2016 | B25: 08.014.346/0001-50 | C25: 3M MANAUS INDUSTRIA DE PRODUTOS QUIMICOS LTDA | D25: 3M MANAUS | E25: AMAZONAS | F25: MANAUS | G25: 20991 - Fabricação de produtos químicos não especificados anteriormente | H25: Declarado pelo Contribuinte para Apuração do IRPJ e da CSLL | I25: Sudam/Sudene - Redução por Reinvestimento | J25: 1595725.7 | K25: =IFERROR(J25*VLOOKUP(A25,IPCA_Fatores!$A$2:$C$10,3,FALSE),J25) -> 2553185.3
A26: 2017 | B26: 08.014.346/0001-50 | C26: 3M MANAUS INDUSTRIA DE PRODUTOS QUIMICOS LTDA | D26: 3M MANAUS | E26: AMAZONAS | F26: MANAUS | G26: 20991 - Fabricação de produtos químicos não especificados anteriormente | H26: Declarado pelo Contribuinte para Apuração do IRPJ e da CSLL | I26: Sudam/Sudene - Redução 75% Projeto Setor Prioritário | J26: 38054482 | K26: =J26*_xlfn.XLOOKUP(A26,IPCA_Fatores!$A$2:$A$10,IPCA_Fatores!$C$2:$C$10) -> 59143030
A27: 2017 | B27: 08.014.346/0001-50 | C27: 3M MANAUS INDUSTRIA DE PRODUTOS QUIMICOS LTDA | D27: 3M MANAUS | E27: AMAZONAS | F27: MANAUS | G27: 20991 - Fabricação de produtos químicos não especificados anteriormente | H27: Declarado pelo Contribuinte para Apuração do IRPJ e da CSLL | I27: Sudam/Sudene - Redução por Reinvestimento | J27: 2284245.5 | K27: =IFERROR(J27*VLOOKUP(A27,IPCA_Fatores!$A$2:$C$10,3,FALSE),J27) -> 3550099.5
A28: 2018 | B28: 08.014.346/0001-50 | C28: 3M MANAUS INDUSTRIA DE PRODUTOS QUIMICOS LTDA | D28: 3M MANAUS | E28: AMAZONAS | F28: MANAUS | G28: 20991 - Fabricação de produtos químicos não especificados anteriormente | H28: Declarado pelo Contribuinte para Apuração do IRPJ e da CSLL | I28: Sudam/Sudene - Redução 75% Projeto Setor Prioritário | J28: 44338040 | K28: =J28*_xlfn.XLOOKUP(A28,IPCA_Fatores!$A$2:$A$10,IPCA_Fatores!$C$2:$C$10) -> 66418052
A29: 2018 | B29: 08.014.346/0001-50 | C29: 3M MANAUS INDUSTRIA DE PRODUTOS QUIMICOS LTDA | D29: 3M MANAUS | E29: AMAZONAS | F29: MANAUS | G29: 20991 - Fabricação de produtos químicos não especificados anteriormente | H29: Declarado pelo Contribuinte para Apuração do IRPJ e da CSLL | I29: Sudam/Sudene - Redução por Reinvestimento | J29: 2661323.7 | K29: =IFERROR(J29*VLOOKUP(A29,IPCA_Fatores!$A$2:$C$10,3,FALSE),J29) -> 3986643
A30: 2019 | B30: 08.014.346/0001-50 | C30: 3M MANAUS INDUSTRIA DE PRODUTOS QUIMICOS LTDA | D30: 3M MANAUS | E30: AMAZONAS | F30: MANAUS | G30: 20991 - Fabricação de produtos químicos não especificados anteriormente | H30: Declarado pelo Contribuinte para Apuração do IRPJ e da CSLL | I30: Sudam/Sudene - Redução 75% Projeto Setor Prioritário | J30: 47100887 | K30: =J30*_xlfn.XLOOKUP(A30,IPCA_Fatores!$A$2:$A$10,IPCA_Fatores!$C$2:$C$10) -> 67641430
A31: 2019 | B31: 08.014.346/0001-50 | C31: 3M MANAUS INDUSTRIA DE PRODUTOS QUIMICOS LTDA | D31: 3M MANAUS | E31: AMAZONAS | F31: MANAUS | G31: 20991 - Fabricação de produtos químicos não especificados anteriormente | H31: Declarado pelo Contribuinte para Apuração do IRPJ e da CSLL | I31: Sudam/Sudene - Redução por Reinvestimento | J31: 2644607.2 | K31: =IFERROR(J31*VLOOKUP(A31,IPCA_Fatores!$A$2:$C$10,3,FALSE),J31) -> 3797911.8
A32: 2020 | B32: 08.014.346/0001-50 | C32: 3M MANAUS INDUSTRIA DE PRODUTOS QUIMICOS LTDA | D32: 3M MANAUS | E32: AMAZONAS | F32: MANAUS | G32: 20991 - Fabricação de produtos químicos não especificados anteriormente | H32: Declarado pelo Contribuinte para Apuração do IRPJ e da CSLL | I32: Sudam/Sudene - Redução 75% Projeto Setor Prioritário | J32: 54492139 | K32: =J32*_xlfn.XLOOKUP(A32,IPCA_Fatores!$A$2:$A$10,IPCA_Fatores!$C$2:$C$10) -> 74871780
A33: 2020 | B33: 08.014.346/0001-50 | C33: 3M MANAUS INDUSTRIA DE PRODUTOS QUIMICOS LTDA | D33: 3M MANAUS | E33: AMAZONAS | F33: MANAUS | G33: 20991 - Fabricação de produtos químicos não especificados anteriormente | H33: Declarado pelo Contribuinte para Apuração do IRPJ e da CSLL | I33: Sudam/Sudene - Redução por Reinvestimento | J33: 3270539 | K33: =IFERROR(J33*VLOOKUP(A33,IPCA_Fatores!$A$2:$C$10,3,FALSE),J33) -> 4493695.4
A34: 2021 | B34: 08.014.346/0001-50 | C34: 3M MANAUS INDUSTRIA DE PRODUTOS QUIMICOS LTDA | D34: 3M MANAUS | E34: AMAZONAS | F34: MANAUS | G34: 20991 - Fabricação de produtos químicos não especificados anteriormente | H34: Declarado pelo Contribuinte para Apuração do IRPJ e da CSLL | I34: Sudam/Sudene - Redução 75% Projeto Setor Prioritário | J34: 51030560 | K34: =J34*_xlfn.XLOOKUP(A34,IPCA_Fatores!$A$2:$A$10,IPCA_Fatores!$C$2:$C$10) -> 63706703
A35: 2021 | B35: 08.014.346/0001-50 | C35: 3M MANAUS INDUSTRIA DE PRODUTOS QUIMICOS LTDA | D35: 3M MANAUS | E35: AMAZONAS | F35: MANAUS | G35: 20991 - Fabricação de produtos químicos não especificados anteriormente | H35: Declarado pelo Contribuinte para Apuração do IRPJ e da CSLL | I35: Sudam/Sudene - Redução por Reinvestimento | J35: 3062805.3 | K35: =IFERROR(J35*VLOOKUP(A35,IPCA_Fatores!$A$2:$C$10,3,FALSE),J35) -> 3823615.2
A36: 2022 | B36: 08.014.346/0001-50 | C36: 3M MANAUS INDUSTRIA DE PRODUTOS QUIMICOS LTDA | D36: 3M MANAUS | E36: AMAZONAS | F36: MANAUS | G36: 20991 - Fabricação de produtos químicos não especificados anteriormente | H36: Declarado pelo Contribuinte para Apuração do IRPJ e da CSLL | I36: Sudam/Sudene - Redução 75% Projeto Setor Prioritário | J36: 73867064 | K36: =J36*_xlfn.XLOOKUP(A36,IPCA_Fatores!$A$2:$A$10,IPCA_Fatores!$C$2:$C$10) -> 87168789
A37: 2022 | B37: 08.014.346/0001-50 | C37: 3M MANAUS INDUSTRIA DE PRODUTOS QUIMICOS LTDA | D37: 3M MANAUS | E37: AMAZONAS | F37: MANAUS | G37: 20991 - Fabricação de produtos químicos não especificados anteriormente | H37: Declarado pelo Contribuinte para Apuração do IRPJ e da CSLL | I37: Sudam/Sudene - Redução por Reinvestimento | J37: 4462963.2 | K37: =IFERROR(J37*VLOOKUP(A37,IPCA_Fatores!$A$2:$C$10,3,FALSE),J37) -> 5266638.1
A38: 2023 | B38: 08.014.346/0001-50 | C38: 3M MANAUS INDUSTRIA DE PRODUTOS QUIMICOS LTDA | D38: 3M MANAUS | E38: AMAZONAS | F38: MANAUS | G38: 20991 - Fabricação de produtos químicos não especificados anteriormente | H38: Declarado pelo Contribuinte para Apuração do IRPJ e da CSLL | I38: Sudam/Sudene - Redução 75% Projeto Setor Prioritário | J38: 80781988 | K38: =J38*_xlfn.XLOOKUP(A38,IPCA_Fatores!$A$2:$A$10,IPCA_Fatores!$C$2:$C$10) -> 91119221
A39: 2023 | B39: 08.014.346/0001-50 | C39: 3M MANAUS INDUSTRIA DE PRODUTOS QUIMICOS LTDA | D39: 3M MANAUS | E39: AMAZONAS | F39: MANAUS | G39: 20991 - Fabricação de produtos químicos não especificados anteriormente | H39: Declarado pelo Contribuinte para Apuração do IRPJ e da CSLL | I39: Sudam/Sudene - Redução por Reinvestimento | J39: 4848181.7 | K39: =IFERROR(J39*VLOOKUP(A39,IPCA_Fatores!$A$2:$C$10,3,FALSE),J39) -> 5468577.2
A40: 2023 | B40: 23.018.639/0001-08 | C40: 3R BAHIA S.A | E40: RIO DE JANEIRO | F40: RIO DE JANEIRO | G40: 06000 - Extração de petróleo e gás natural | H40: Declarado pelo Contribuinte para Apuração do IRPJ e da CSLL | I40: Sudam/Sudene - Redução 75% Projeto Setor Prioritário | J40: 821967.92 | K40: =J40*_xlfn.XLOOKUP(A40,IPCA_Fatores!$A$2:$A$10,IPCA_Fatores!$C$2:$C$10) -> 927150.69
...

Sheet IPCA_Fatores
A1: Ano-Calendário | B1: Data-base | C1: Fator IPCA até 31/05/2026 | D1: Fonte/observação
A2: 2015 | B2: 31/12/2015 | C2: 1.7006561 | D2: Fator acumulado de jan do ano seguinte até mai/2026 (IPCA)
A3: 2016 | B3: 31/12/2016 | C3: 1.6000152 | D3: Fator acumulado de jan do ano seguinte até mai/2026 (IPCA)
A4: 2017 | B4: 31/12/2017 | C4: 1.5541672 | D4: Fator acumulado de jan do ano seguinte até mai/2026 (IPCA)
A5: 2018 | B5: 31/12/2018 | C5: 1.4979925 | D5: Fator acumulado de jan do ano seguinte até mai/2026 (IPCA)
A6: 2019 | B6: 31/12/2019 | C6: 1.4360968 | D6: Fator acumulado de jan do ano seguinte até mai/2026 (IPCA)
A7: 2020 | B7: 31/12/2020 | C7: 1.3739923 | D7: Fator acumulado de jan do ano seguinte até mai/2026 (IPCA)
A8: 2021 | B8: 31/12/2021 | C8: 1.248403 | D8: Fator acumulado de jan do ano seguinte até mai/2026 (IPCA)
A9: 2022 | B9: 31/12/2022 | C9: 1.1800765 | D9: Fator acumulado de jan do ano seguinte até mai/2026 (IPCA)
A10: 2023 | B10: 31/12/2023 | C10: 1.1279646 | D10: Fator acumulado de jan do ano seguinte até mai/2026 (IPCA)

Sheet Resumo_por_Empresa
A1: Nº | B1: Beneficiário | C1: Total Valor Renunciado (R$) | D1: Total Valor Atualizado IPCA (R$)
A2: =ROW()-1 -> 1 | B2: {=_xlfn._xlws.SORT(_xlfn.UNIQUE('Renúncias Fiscais Sudam-Sudene'!C2:C11311))} -> 1TELECOM SERVICOS DE TECNOLOGIA EM INTERNET LTDA | C2: =SUMIF('Renúncias Fiscais Sudam-Sudene'!C:C,B2,'Renúncias Fiscais Sudam-Sudene'!J:J) -> 4236763.1 | D2: =SUMIF('Renúncias Fiscais Sudam-Sudene'!C:C,B2,'Renúncias Fiscais Sudam-Sudene'!K:K) -> 5256781.8
A3: =ROW()-1 -> 2 | B3: 2 J COMERCIAL LTDA | C3: =SUMIF('Renúncias Fiscais Sudam-Sudene'!C:C,B3,'Renúncias Fiscais Sudam-Sudene'!J:J) -> 870884.36 | D3: =SUMIF('Renúncias Fiscais Sudam-Sudene'!C:C,B3,'Renúncias Fiscais Sudam-Sudene'!K:K) -> 982326.7
A4: =ROW()-1 -> 3 | B4: 3CAFFI INDUSTRIA E COMERCIO DE CAPSULAS S.A | C4: =SUMIF('Renúncias Fiscais Sudam-Sudene'!C:C,B4,'Renúncias Fiscais Sudam-Sudene'!J:J) -> 28230398 | D4: =SUMIF('Renúncias Fiscais Sudam-Sudene'!C:C,B4,'Renúncias Fiscais Sudam-Sudene'!K:K) -> 35206574
A5: =ROW()-1 -> 4 | B5: 3M MANAUS INDUSTRIA DE PRODUTOS QUIMICOS LTDA | C5: =SUMIF('Renúncias Fiscais Sudam-Sudene'!C:C,B5,'Renúncias Fiscais Sudam-Sudene'!J:J) -> 4.5758889e+08 | D5: =SUMIF('Renúncias Fiscais Sudam-Sudene'!C:C,B5,'Renúncias Fiscais Sudam-Sudene'!K:K) -> 6.1362146e+08
A6: =ROW()-1 -> 5 | B6: 3R BAHIA S.A | C6: =SUMIF('Renúncias Fiscais Sudam-Sudene'!C:C,B6,'Renúncias Fiscais Sudam-Sudene'!J:J) -> 821967.92 | D6: =SUMIF('Renúncias Fiscais Sudam-Sudene'!C:C,B6,'Renúncias Fiscais Sudam-Sudene'!K:K) -> 927150.69
A7: =ROW()-1 -> 6 | B7: 3R MACAU S.A. | C7: =SUMIF('Renúncias Fiscais Sudam-Sudene'!C:C,B7,'Renúncias Fiscais Sudam-Sudene'!J:J) -> 1.6969539e+08 | D7: =SUMIF('Renúncias Fiscais Sudam-Sudene'!C:C,B7,'Renúncias Fiscais Sudam-Sudene'!K:K) -> 1.961142e+08
A8: =ROW()-1 -> 7 | B8: 3R PETROLEUM OFFSHORE S.A. | C8: =SUMIF('Renúncias Fiscais Sudam-Sudene'!C:C,B8,'Renúncias Fiscais Sudam-Sudene'!J:J) -> 7294881.1 | D8: =SUMIF('Renúncias Fiscais Sudam-Sudene'!C:C,B8,'Renúncias Fiscais Sudam-Sudene'!K:K) -> 8228367.4
A9: =ROW()-1 -> 8 | B9: 3R POTIGUAR S.A. | C9: =SUMIF('Renúncias Fiscais Sudam-Sudene'!C:C,B9,'Renúncias Fiscais Sudam-Sudene'!J:J) -> 7504086.4 | D9: =SUMIF('Renúncias Fiscais Sudam-Sudene'!C:C,B9,'Renúncias Fiscais Sudam-Sudene'!K:K) -> 8464343.5
A10: =ROW()-1 -> 9 | B10: 3R RIO VENTURA S.A. | C10: =SUMIF('Renúncias Fiscais Sudam-Sudene'!C:C,B10,'Renúncias Fiscais Sudam-Sudene'!J:J) -> 22933753 | D10: =SUMIF('Renúncias Fiscais Sudam-Sudene'!C:C,B10,'Renúncias Fiscais Sudam-Sudene'!K:K) -> 26237968
A11: =ROW()-1 -> 10 | B11: 3R RNCE S.A. | C11: =SUMIF('Renúncias Fiscais Sudam-Sudene'!C:C,B11,'Renúncias Fiscais Sudam-Sudene'!J:J) -> 7517803.1 | D11: =SUMIF('Renúncias Fiscais Sudam-Sudene'!C:C,B11,'Renúncias Fiscais Sudam-Sudene'!K:K) -> 8676970.4
A12: =ROW()-1 -> 11 | B12: A ALVES DE SOUSA INDUSTRIA E COMERCIO DE MOTOS LTDA | C12: =SUMIF('Renúncias Fiscais Sudam-Sudene'!C:C,B12,'Renúncias Fiscais Sudam-Sudene'!J:J) -> 6289680.5 | D12: =SUMIF('Renúncias Fiscais Sudam-Sudene'!C:C,B12,'Renúncias Fiscais Sudam-Sudene'!K:K) -> 7663853.3
A13: =ROW()-1 -> 12 | B13: A G HOTEIS E TURISMO S/A | C13: =SUMIF('Renúncias Fiscais Sudam-Sudene'!C:C,B13,'Renúncias Fiscais Sudam-Sudene'!J:J) -> 7566596.7 | D13: =SUMIF('Renúncias Fiscais Sudam-Sudene'!C:C,B13,'Renúncias Fiscais Sudam-Sudene'!K:K) -> 10040665
A14: =ROW()-1 -> 13 | B14: A T S - TERCEIRIZACAO DE MAO DE OBRA LTDA | C14: =SUMIF('Renúncias Fiscais Sudam-Sudene'!C:C,B14,'Renúncias Fiscais Sudam-Sudene'!J:J) -> 673582.76 | D14: =SUMIF('Renúncias Fiscais Sudam-Sudene'!C:C,B14,'Renúncias Fiscais Sudam-Sudene'!K:K) -> 759777.49
... A2248: =ROW()-1 -> 2247 | B2248: ZTT DO BRASIL LTDA | C2248: =SUMIF('Renúncias Fiscais Sudam-Sudene'!C:C,B2248,'Renúncias Fiscais Sudam-Sudene'!J:J) -> 3518118.7 | D2248: =SUMIF('Renúncias Fiscais Sudam-Sudene'!C:C,B2248,'Renúncias Fiscais Sudam-Sudene'!K:K) -> 4810114
B2249: TOTAL GERAL | C2249: =SUM(C2:C2248) -> 1.2648412e+11 | D2249: =SUM(D2:D2248) -> 1.6624748e+11
